#VRML_SIM R2022a utf8
# license: Apache License 2.0
# license url: http://www.apache.org/licenses/LICENSE-2.0
# This is a proto file for Webots for the WheelLeg
# Extracted from: ../urdf/WheelLeg.urdf

PROTO WheelLeg [
  field  SFVec3f     translation     0 0 0
  field  SFRotation  rotation        0 0 1 0
  field  SFString    name            "WheelLeg"  # Is `Robot.name`.
  field  SFString    controller      "void"      # Is `Robot.controller`.
  field  MFString    controllerArgs  []          # Is `Robot.controllerArgs`.
  field  SFString    customData      ""          # Is `Robot.customData`.
  field  SFBool      supervisor      FALSE       # Is `Robot.supervisor`.
  field  SFBool      synchronization TRUE        # Is `Robot.synchronization`.
  field  SFBool      selfCollision   FALSE       # Is `Robot.selfCollision`.
]
{
  Robot {
    translation IS translation
    rotation IS rotation
    controller IS controller
    controllerArgs IS controllerArgs
    customData IS customData
    supervisor IS supervisor
    synchronization IS synchronization
    selfCollision IS selfCollision
    children [
      Shape {
        appearance DEF Cyan PBRAppearance {
          baseColor 0.000000 1.000000 1.000000
          transparency 0.000000
          roughness 1.000000
          metalness 0
          emissiveColor 0.000000 0.000000 0.000000
        }
        geometry Box {
           size 0.1 0.1 0.1
        }
      }
      HingeJoint {
        jointParameters HingeJointParameters {
          axis -0.000011 1.000000 0.000000
          anchor 0.400000 0.200000 0.020000
          dampingConstant 0.0
          staticFriction 0.0
        }
        device [
          RotationalMotor {
            name "LF_Joint"

          }
          PositionSensor {
            name "LF_Joint_sensor"
          }
        ]
        endPoint Solid {
          translation 0.400000 0.200000 0.020000
          rotation 0.577350 0.577354 0.577347 4.188799
          children [
            Shape {
              appearance DEF LF_material PBRAppearance {
                baseColor 1.000000 1.000000 1.000000
                transparency 0.000000
                roughness 1.000000
                metalness 0
                emissiveColor 0.000000 0.000000 0.000000
              }
              geometry DEF Left Mesh {
                url "../meshes/Left.STL"
              }
            }
            HingeJoint {
              jointParameters HingeJointParameters {
                axis -0.000007 -0.000000 -1.000000
                anchor 0.000000 -0.080000 0.038242
                dampingConstant 0.2
                staticFriction 0.0
              }
              device [
                RotationalMotor {
                  name "LFRA_Joint"
                  maxVelocity 30.0
                  maxTorque 2.8
                }
                PositionSensor {
                  name "LFRA_Joint_sensor"
                }
              ]
              endPoint Solid {
                translation 0.000000 -0.080000 0.038242
                rotation 0.707105 0.707108 -0.000003 3.141598
                children [
                  Shape {
                    appearance DEF LFRA_material PBRAppearance {
                      baseColor 1.000000 1.000000 1.000000
                      transparency 0.000000
                      roughness 1.000000
                      metalness 0
                      emissiveColor 0.000000 0.000000 0.000000
                    }
                    geometry DEF LeftRimA Mesh {
                      url "../meshes/LeftRimA.STL"
                    }
                  }
                ]
                name "LFRA"
                boundingObject USE LeftRimA
                physics Physics {
                  density -1
                  mass 0.102066
                  centerOfMass [ 0.060621 -0.050905 -0.016080 ]
                  inertiaMatrix [
                    1.076188e-04 4.265116e-04 5.135004e-04
                    6.405805e-05 1.407215e-07 -2.255696e-07
                  ]
                }
              }
            }
            HingeJoint {
              jointParameters HingeJointParameters {
                axis 0.000007 -0.000000 -1.000000
                anchor 0.000000 0.080000 0.038242
                dampingConstant 0.2
                staticFriction 0.0
              }
              device [
                RotationalMotor {
                  name "LFRB_Joint"
                  maxVelocity 30.0
                  maxTorque 2.8
                }
                PositionSensor {
                  name "LFRB_Joint_sensor"
                }
              ]
              endPoint Solid {
                translation 0.000000 0.080000 0.038242
                rotation 0.707105 -0.707108 0.000003 3.141598
                children [
                  Shape {
                    appearance DEF LFRB_material PBRAppearance {
                      baseColor 1.000000 1.000000 1.000000
                      transparency 0.000000
                      roughness 1.000000
                      metalness 0
                      emissiveColor 0.000000 0.000000 0.000000
                    }
                    geometry DEF LeftRimB Mesh {
                      url "../meshes/LeftRimB.STL"
                    }
                  }
                ]
                name "LFRB"
                boundingObject USE LeftRimB
                physics Physics {
                  density -1
                  mass 0.102066
                  centerOfMass [ 0.060621 -0.050905 -0.016080 ]
                  inertiaMatrix [
                    1.076188e-04 4.265116e-04 5.135004e-04
                    6.405805e-05 1.407215e-07 -2.255696e-07
                  ]
                }
              }
            }
          ]
          name "LF"
          boundingObject USE Left
          physics Physics {
            density -1
            mass 0.075119
            centerOfMass [ 0.000000 0.000002 0.045042 ]
            inertiaMatrix [
              1.056500e-04 2.754600e-05 9.665500e-05
              -1.064900e-07 -2.347900e-12 -8.930800e-10
            ]
          }
        }
      }
      HingeJoint {
        jointParameters HingeJointParameters {
          axis -0.000011 1.000000 0.000000
          anchor 0.000000 0.300000 0.020000
          dampingConstant 0.0
          staticFriction 0.0
        }
        device [
          RotationalMotor {
            name "LM_Joint"

          }
          PositionSensor {
            name "LM_Joint_sensor"
          }
        ]
        endPoint Solid {
          translation 0.000000 0.300000 0.020000
          rotation 0.577350 0.577354 0.577347 4.188799
          children [
            Shape {
              appearance DEF LM_material PBRAppearance {
                baseColor 1.000000 1.000000 1.000000
                transparency 0.000000
                roughness 1.000000
                metalness 0
                emissiveColor 0.000000 0.000000 0.000000
              }
              geometry USE Left
            }
            HingeJoint {
              jointParameters HingeJointParameters {
                axis -0.000007 -0.000000 -1.000000
                anchor 0.000000 -0.080000 0.038242
                dampingConstant 0.2
                staticFriction 0.0
              }
              device [
                RotationalMotor {
                  name "LMRA_Joint"
                  maxVelocity 30.0
                  maxTorque 2.8
                }
                PositionSensor {
                  name "LMRA_Joint_sensor"
                }
              ]
              endPoint Solid {
                translation 0.000000 -0.080000 0.038242
                rotation 0.707105 0.707108 -0.000003 3.141598
                children [
                  Shape {
                    appearance DEF LMRA_material PBRAppearance {
                      baseColor 1.000000 1.000000 1.000000
                      transparency 0.000000
                      roughness 1.000000
                      metalness 0
                      emissiveColor 0.000000 0.000000 0.000000
                    }
                    geometry USE LeftRimA
                  }
                ]
                name "LMRA"
                boundingObject USE LeftRimA
                physics Physics {
                  density -1
                  mass 0.102066
                  centerOfMass [ 0.060621 -0.050905 -0.016080 ]
                  inertiaMatrix [
                    1.076188e-04 4.265116e-04 5.135004e-04
                    6.405805e-05 1.407215e-07 -2.255696e-07
                  ]
                }
              }
            }
            HingeJoint {
              jointParameters HingeJointParameters {
                axis 0.000007 -0.000000 -1.000000
                anchor 0.000000 0.080000 0.038242
                dampingConstant 0.2
                staticFriction 0.0
              }
              device [
                RotationalMotor {
                  name "LMRB_Joint"
                  maxVelocity 30.0
                  maxTorque 2.8
                }
                PositionSensor {
                  name "LMRB_Joint_sensor"
                }
              ]
              endPoint Solid {
                translation 0.000000 0.080000 0.038242
                rotation 0.707105 -0.707108 0.000003 3.141598
                children [
                  Shape {
                    appearance DEF LMRB_material PBRAppearance {
                      baseColor 1.000000 1.000000 1.000000
                      transparency 0.000000
                      roughness 1.000000
                      metalness 0
                      emissiveColor 0.000000 0.000000 0.000000
                    }
                    geometry USE LeftRimB
                  }
                ]
                name "LMRB"
                boundingObject USE LeftRimB
                physics Physics {
                  density -1
                  mass 0.102066
                  centerOfMass [ 0.060621 -0.050905 -0.016080 ]
                  inertiaMatrix [
                    1.076188e-04 4.265116e-04 5.135004e-04
                    6.405805e-05 1.407215e-07 -2.255696e-07
                  ]
                }
              }
            }
          ]
          name "LM"
          boundingObject USE Left
          physics Physics {
            density -1
            mass 0.075119
            centerOfMass [ 0.000000 0.000002 0.045042 ]
            inertiaMatrix [
              1.056500e-04 2.754600e-05 9.665500e-05
              -1.064900e-07 -2.347900e-12 -8.930800e-10
            ]
          }
        }
      }
      HingeJoint {
        jointParameters HingeJointParameters {
          axis -0.000011 1.000000 0.000000
          anchor -0.400000 0.200000 0.020000
          dampingConstant 0.0
          staticFriction 0.0
        }
        device [
          RotationalMotor {
            name "LB_Joint"

          }
          PositionSensor {
            name "LB_Joint_sensor"
          }
        ]
        endPoint Solid {
          translation -0.400000 0.200000 0.020000
          rotation 0.577350 0.577354 0.577347 4.188799
          children [
            Shape {
              appearance DEF LB_material PBRAppearance {
                baseColor 1.000000 1.000000 1.000000
                transparency 0.000000
                roughness 1.000000
                metalness 0
                emissiveColor 0.000000 0.000000 0.000000
              }
              geometry USE Left
            }
            HingeJoint {
              jointParameters HingeJointParameters {
                axis -0.000007 -0.000000 -1.000000
                anchor 0.000000 -0.080000 0.038242
                dampingConstant 0.2
                staticFriction 0.0
              }
              device [
                RotationalMotor {
                  name "LBRA_Joint"
                  maxVelocity 30.0
                  maxTorque 2.8
                }
                PositionSensor {
                  name "LBRA_Joint_sensor"
                }
              ]
              endPoint Solid {
                translation 0.000000 -0.080000 0.038242
                rotation 0.707105 0.707108 -0.000003 3.141598
                children [
                  Shape {
                    appearance DEF LBRA_material PBRAppearance {
                      baseColor 1.000000 1.000000 1.000000
                      transparency 0.000000
                      roughness 1.000000
                      metalness 0
                      emissiveColor 0.000000 0.000000 0.000000
                    }
                    geometry USE LeftRimA
                  }
                ]
                name "LBRA"
                boundingObject USE LeftRimA
                physics Physics {
                  density -1
                  mass 0.102066
                  centerOfMass [ 0.060621 -0.050905 -0.016080 ]
                  inertiaMatrix [
                    1.076188e-04 4.265116e-04 5.135004e-04
                    6.405805e-05 1.407215e-07 -2.255696e-07
                  ]
                }
              }
            }
            HingeJoint {
              jointParameters HingeJointParameters {
                axis 0.000007 -0.000000 -1.000000
                anchor 0.000000 0.080000 0.038242
                dampingConstant 0.2
                staticFriction 0.0
              }
              device [
                RotationalMotor {
                  name "LBRB_Joint"
                  maxVelocity 30.0
                  maxTorque 2.8
                }
                PositionSensor {
                  name "LBRB_Joint_sensor"
                }
              ]
              endPoint Solid {
                translation 0.000000 0.080000 0.038242
                rotation 0.707105 -0.707108 0.000003 3.141598
                children [
                  Shape {
                    appearance DEF LBRB_material PBRAppearance {
                      baseColor 1.000000 1.000000 1.000000
                      transparency 0.000000
                      roughness 1.000000
                      metalness 0
                      emissiveColor 0.000000 0.000000 0.000000
                    }
                    geometry USE LeftRimB
                  }
                ]
                name "LBRB"
                boundingObject USE LeftRimB
                physics Physics {
                  density -1
                  mass 0.102066
                  centerOfMass [ 0.060621 -0.050905 -0.016080 ]
                  inertiaMatrix [
                    1.076188e-04 4.265116e-04 5.135004e-04
                    6.405805e-05 1.407215e-07 -2.255696e-07
                  ]
                }
              }
            }
          ]
          name "LB"
          boundingObject USE Left
          physics Physics {
            density -1
            mass 0.075119
            centerOfMass [ 0.000000 0.000002 0.045042 ]
            inertiaMatrix [
              1.056500e-04 2.754600e-05 9.665500e-05
              -1.064900e-07 -2.347900e-12 -8.930800e-10
            ]
          }
        }
      }
      HingeJoint {
        jointParameters HingeJointParameters {
          axis -0.000004 -1.000000 0.000000
          anchor 0.400000 -0.200000 0.020000
          dampingConstant 0.0
          staticFriction 0.0
        }
        device [
          RotationalMotor {
            name "RF_Joint"

          }
          PositionSensor {
            name "RF_Joint_sensor"
          }
        ]
        endPoint Solid {
          translation 0.400000 -0.200000 0.020000
          rotation 0.577350 0.577350 -0.577352 2.094399
          children [
            Shape {
              appearance DEF RF_material PBRAppearance {
                baseColor 1.000000 1.000000 1.000000
                transparency 0.000000
                roughness 1.000000
                metalness 0
                emissiveColor 0.000000 0.000000 0.000000
              }
              geometry DEF Right Mesh {
                url "../meshes/Right.STL"
              }
            }
            HingeJoint {
              jointParameters HingeJointParameters {
                axis 0.000000 0.000000 1.000000
                anchor 0.000000 -0.080000 0.038244
                dampingConstant 0.2
                staticFriction 0.0
              }
              device [
                RotationalMotor {
                  name "RFRA_Joint"
                  maxVelocity 30.0
                  maxTorque 2.8
                }
                PositionSensor {
                  name "RFRA_Joint_sensor"
                }
              ]
              endPoint Solid {
                translation 0.000000 -0.080000 0.038244
                rotation 0.000000 0.000000 1.000000 1.570800
                children [
                  Shape {
                    appearance DEF RFRA_material PBRAppearance {
                      baseColor 1.000000 1.000000 1.000000
                      transparency 0.000000
                      roughness 1.000000
                      metalness 0
                      emissiveColor 0.000000 0.000000 0.000000
                    }
                    geometry DEF RightRimA Mesh {
                      url "../meshes/RightRimA.STL"
                    }
                  }
                ]
                name "RFRA"
                boundingObject USE RightRimA
                physics Physics {
                  density -1
                  mass 0.102066
                  centerOfMass [ 0.060621 -0.050905 0.015934 ]
                  inertiaMatrix [
                    1.076188e-04 4.265116e-04 5.135004e-04
                    6.405805e-05 1.407215e-07 -2.255696e-07
                  ]
                }
              }
            }
            HingeJoint {
              jointParameters HingeJointParameters {
                axis 0.000000 -0.000000 1.000000
                anchor 0.000000 0.080000 0.038244
                dampingConstant 0.2
                staticFriction 0.0
              }
              device [
                RotationalMotor {
                  name "RFRB_Joint"
                  maxVelocity 30.0
                  maxTorque 2.8
                }
                PositionSensor {
                  name "RFRB_Joint_sensor"
                }
              ]
              endPoint Solid {
                translation 0.000000 0.080000 0.038244
                rotation 0.000000 0.000000 -1.000000 1.570800
                children [
                  Shape {
                    appearance DEF RFRB_material PBRAppearance {
                      baseColor 1.000000 1.000000 1.000000
                      transparency 0.000000
                      roughness 1.000000
                      metalness 0
                      emissiveColor 0.000000 0.000000 0.000000
                    }
                    geometry DEF RightRimB Mesh {
                      url "../meshes/RightRimB.STL"
                    }
                  }
                ]
                name "RFRB"
                boundingObject USE RightRimB
                physics Physics {
                  density -1
                  mass 0.102066
                  centerOfMass [ 0.060621 -0.050905 0.015934 ]
                  inertiaMatrix [
                    1.076188e-04 4.265116e-04 5.135004e-04
                    6.405805e-05 1.407215e-07 -2.255696e-07
                  ]
                }
              }
            }
          ]
          name "RF"
          boundingObject USE Right
          physics Physics {
            density -1
            mass 0.075119
            centerOfMass [ 0.000000 0.000002 0.045042 ]
            inertiaMatrix [
              1.056500e-04 2.754600e-05 9.665500e-05
              -1.064900e-07 -2.347900e-12 -8.930800e-10
            ]
          }
        }
      }
      HingeJoint {
        jointParameters HingeJointParameters {
          axis -0.000004 -1.000000 0.000000
          anchor 0.000000 -0.300000 0.020000
          dampingConstant 0.0
          staticFriction 0.0
        }
        device [
          RotationalMotor {
            name "RM_Joint"

          }
          PositionSensor {
            name "RM_Joint_sensor"
          }
        ]
        endPoint Solid {
          translation 0.000000 -0.300000 0.020000
          rotation 0.577350 0.577350 -0.577352 2.094399
          children [
            Shape {
              appearance DEF RM_material PBRAppearance {
                baseColor 1.000000 1.000000 1.000000
                transparency 0.000000
                roughness 1.000000
                metalness 0
                emissiveColor 0.000000 0.000000 0.000000
              }
              geometry USE Right
            }
            HingeJoint {
              jointParameters HingeJointParameters {
                axis 0.000000 0.000000 1.000000
                anchor 0.000000 -0.080000 0.038244
                dampingConstant 0.2
                staticFriction 0.0
              }
              device [
                RotationalMotor {
                  name "RMRA_Joint"
                  maxVelocity 30.0
                  maxTorque 2.8
                }
                PositionSensor {
                  name "RMRA_Joint_sensor"
                }
              ]
              endPoint Solid {
                translation 0.000000 -0.080000 0.038244
                rotation 0.000000 0.000000 1.000000 1.570800
                children [
                  Shape {
                    appearance DEF RMRA_material PBRAppearance {
                      baseColor 1.000000 1.000000 1.000000
                      transparency 0.000000
                      roughness 1.000000
                      metalness 0
                      emissiveColor 0.000000 0.000000 0.000000
                    }
                    geometry USE RightRimA
                  }
                ]
                name "RMRA"
                boundingObject USE RightRimA
                physics Physics {
                  density -1
                  mass 0.102066
                  centerOfMass [ 0.060621 -0.050905 0.015934 ]
                  inertiaMatrix [
                    1.076188e-04 4.265116e-04 5.135004e-04
                    6.405805e-05 1.407215e-07 -2.255696e-07
                  ]
                }
              }
            }
            HingeJoint {
              jointParameters HingeJointParameters {
                axis 0.000000 -0.000000 1.000000
                anchor 0.000000 0.080000 0.038244
                dampingConstant 0.2
                staticFriction 0.0
              }
              device [
                RotationalMotor {
                  name "RMRB_Joint"
                  maxVelocity 30.0
                  maxTorque 2.8
                }
                PositionSensor {
                  name "RMRB_Joint_sensor"
                }
              ]
              endPoint Solid {
                translation 0.000000 0.080000 0.038244
                rotation 0.000000 0.000000 -1.000000 1.570800
                children [
                  Shape {
                    appearance DEF RMRB_material PBRAppearance {
                      baseColor 1.000000 1.000000 1.000000
                      transparency 0.000000
                      roughness 1.000000
                      metalness 0
                      emissiveColor 0.000000 0.000000 0.000000
                    }
                    geometry USE RightRimB
                  }
                ]
                name "RMRB"
                boundingObject USE RightRimB
                physics Physics {
                  density -1
                  mass 0.102066
                  centerOfMass [ 0.060621 -0.050905 0.015934 ]
                  inertiaMatrix [
                    1.076188e-04 4.265116e-04 5.135004e-04
                    6.405805e-05 1.407215e-07 -2.255696e-07
                  ]
                }
              }
            }
          ]
          name "RM"
          boundingObject USE Right
          physics Physics {
            density -1
            mass 0.075119
            centerOfMass [ 0.000000 0.000002 0.045042 ]
            inertiaMatrix [
              1.056500e-04 2.754600e-05 9.665500e-05
              -1.064900e-07 -2.347900e-12 -8.930800e-10
            ]
          }
        }
      }
      HingeJoint {
        jointParameters HingeJointParameters {
          axis -0.000004 -1.000000 0.000000
          anchor -0.400000 -0.200000 0.020000
          dampingConstant 0.0
          staticFriction 0.0
        }
        device [
          RotationalMotor {
            name "RB_Joint"

          }
          PositionSensor {
            name "RB_Joint_sensor"
          }
        ]
        endPoint Solid {
          translation -0.400000 -0.200000 0.020000
          rotation 0.577350 0.577350 -0.577352 2.094399
          children [
            Shape {
              appearance DEF RB_material PBRAppearance {
                baseColor 1.000000 1.000000 1.000000
                transparency 0.000000
                roughness 1.000000
                metalness 0
                emissiveColor 0.000000 0.000000 0.000000
              }
              geometry USE Right
            }
            HingeJoint {
              jointParameters HingeJointParameters {
                axis 0.000000 0.000000 1.000000
                anchor 0.000000 -0.080000 0.038244
                dampingConstant 0.2
                staticFriction 0.0
              }
              device [
                RotationalMotor {
                  name "RBRA_Joint"
                  maxVelocity 30.0
                  maxTorque 2.8
                }
                PositionSensor {
                  name "RBRA_Joint_sensor"
                }
              ]
              endPoint Solid {
                translation 0.000000 -0.080000 0.038244
                rotation 0.000000 0.000000 1.000000 1.570800
                children [
                  Shape {
                    appearance DEF RBRA_material PBRAppearance {
                      baseColor 1.000000 1.000000 1.000000
                      transparency 0.000000
                      roughness 1.000000
                      metalness 0
                      emissiveColor 0.000000 0.000000 0.000000
                    }
                    geometry USE RightRimA
                  }
                ]
                name "RBRA"
                boundingObject USE RightRimA
                physics Physics {
                  density -1
                  mass 0.102066
                  centerOfMass [ 0.060621 -0.050905 0.015934 ]
                  inertiaMatrix [
                    1.076188e-04 4.265116e-04 5.135004e-04
                    6.405805e-05 1.407215e-07 -2.255696e-07
                  ]
                }
              }
            }
            HingeJoint {
              jointParameters HingeJointParameters {
                axis 0.000000 -0.000000 1.000000
                anchor 0.000000 0.080000 0.038244
                dampingConstant 0.2
                staticFriction 0.0
              }
              device [
                RotationalMotor {
                  name "RBRB_Joint"
                  maxVelocity 30.0
                  maxTorque 2.8
                }
                PositionSensor {
                  name "RBRB_Joint_sensor"
                }
              ]
              endPoint Solid {
                translation 0.000000 0.080000 0.038244
                rotation 0.000000 0.000000 -1.000000 1.570800
                children [
                  Shape {
                    appearance DEF RBRB_material PBRAppearance {
                      baseColor 1.000000 1.000000 1.000000
                      transparency 0.000000
                      roughness 1.000000
                      metalness 0
                      emissiveColor 0.000000 0.000000 0.000000
                    }
                    geometry USE RightRimB
                  }
                ]
                name "RBRB"
                boundingObject USE RightRimB
                physics Physics {
                  density -1
                  mass 0.102066
                  centerOfMass [ 0.060621 -0.050905 0.015934 ]
                  inertiaMatrix [
                    1.076188e-04 4.265116e-04 5.135004e-04
                    6.405805e-05 1.407215e-07 -2.255696e-07
                  ]
                }
              }
            }
          ]
          name "RB"
          boundingObject USE Right
          physics Physics {
            density -1
            mass 0.075119
            centerOfMass [ 0.000000 0.000002 0.045042 ]
            inertiaMatrix [
              1.056500e-04 2.754600e-05 9.665500e-05
              -1.064900e-07 -2.347900e-12 -8.930800e-10
            ]
          }
        }
      }
    ]
    name IS name
    boundingObject Box {
       size 0.100000 0.100000 0.100000
    }
    physics Physics {
      density -1
      mass 1.000000
      centerOfMass [ 0.050000 0.050000 0.050000 ]
      inertiaMatrix [
        1.670000e-03 1.670000e-03 1.670000e-03
        0.000000e+00 0.000000e+00 0.000000e+00
      ]
    }
  }
}
