<?xml version="1.0" encoding="utf-8"?>
<!-- =================================================================================== -->
<!-- |    This document was autogenerated by xacro from WheelLeg.xacro                 | -->
<!-- |    EDITING THIS FILE BY HAND IS NOT RECOMMENDED                                 | -->
<!-- =================================================================================== -->
<robot name="WheelLeg">
  <link name="base_link">
    <inertial>
      <origin rpy="0 0 0" xyz="0.05 0.05 0.05"/>
      <mass value="1"/>
      <inertia ixx="0.00167" ixy="0" ixz="0" iyy="0.00167" iyz="0" izz="0.00167"/>
    </inertial>
    <visual>
      <origin rpy="0 0 0" xyz="0 0 0"/>
      <geometry>
        <box size="0.1 0.1 0.1"/>
      </geometry>
      <material name="Cyan">
        <color rgba="0 1.0 1.0 1.0"/>
      </material>
    </visual>
    <collision>
      <origin rpy="0 0 0" xyz="0 0 0"/>
      <geometry>
        <box size="0.1 0.1 0.1"/>
      </geometry>
    </collision>
  </link>
  <link name="LF">
    <inertial>
      <origin rpy="0 0 0" xyz="4.8179E-09 1.5313E-06 0.045042"/>
      <mass value="0.075119"/>
      <inertia ixx="0.00010565" ixy="-1.0649E-07" ixz="-2.3479E-12" iyy="2.7546E-05" iyz="-8.9308E-10" izz="9.6655E-05"/>
    </inertial>
    <visual>
      <origin rpy="0 0 0" xyz="0 0 0"/>
      <geometry>
        <mesh filename="package://wheelleg_description/meshes/Left.STL"/>
      </geometry>
      <material name="">
        <color rgba="1 1 1 1"/>
      </material>
    </visual>
    <collision>
      <origin rpy="0 0 0" xyz="0 0 0"/>
      <geometry>
        <mesh filename="package://wheelleg_description/meshes/Left.STL"/>
      </geometry>
    </collision>
  </link>
  <joint name="LF_Joint" type="continuous">
    <origin rpy="1.5708 -1.5708 3.1416" xyz="0.4 0.2 0.02"/>
    <parent link="base_link"/>
    <child link="LF"/>
    <axis xyz="0 0 1"/>
    <limit effort="2.8" velocity="30"/>
  </joint>
  <link name="LFRA">
    <inertial>
      <origin rpy="0 0 0" xyz="0.060620953877514 -0.0509052185223456 -0.0160797180106055"/>
      <mass value="0.102065831041357"/>
      <inertia ixx="0.000107618762660542" ixy="6.4058045299092E-05" ixz="1.40721471251035E-07" iyy="0.000426511611787524" iyz="-2.25569567809916E-07" izz="0.000513500369211842"/>
    </inertial>
    <visual>
      <origin rpy="0 0 0" xyz="0 0 0"/>
      <geometry>
        <mesh filename="package://wheelleg_description/meshes/LeftRimA.STL"/>
      </geometry>
      <material name="">
        <color rgba="1 1 1 1"/>
      </material>
    </visual>
    <collision>
      <origin rpy="0 0 0" xyz="0 0 0"/>
      <geometry>
        <mesh filename="package://wheelleg_description/meshes/LeftRimA.STL"/>
      </geometry>
    </collision>
  </link>
  <joint name="LFRA_Joint" type="continuous">
    <origin rpy="3.1416 0 1.5708" xyz="0 -0.08 0.038242"/>
    <parent link="LF"/>
    <child link="LFRA"/>
    <axis xyz="0 0 1"/>
    <dynamics damping="0.2" friction="0.0"/>
    <limit effort="2.8" velocity="30"/>
  </joint>
  <link name="LFRB">
    <inertial>
      <origin rpy="0 0 0" xyz="0.060620953877514 -0.0509052185223458 -0.0160797180106054"/>
      <mass value="0.102065831041357"/>
      <inertia ixx="0.000107618762660542" ixy="6.4058045299092E-05" ixz="1.40721471251074E-07" iyy="0.000426511611787524" iyz="-2.2556956780994E-07" izz="0.000513500369211842"/>
    </inertial>
    <visual>
      <origin rpy="0 0 0" xyz="0 0 0"/>
      <geometry>
        <mesh filename="package://wheelleg_description/meshes/LeftRimB.STL"/>
      </geometry>
      <material name="">
        <color rgba="1 1 1 1"/>
      </material>
    </visual>
    <collision>
      <origin rpy="0 0 0" xyz="0 0 0"/>
      <geometry>
        <mesh filename="package://wheelleg_description/meshes/LeftRimB.STL"/>
      </geometry>
    </collision>
  </link>
  <joint name="LFRB_Joint" type="continuous">
    <origin rpy="3.1416 0 -1.5708" xyz="0 0.08 0.038242"/>
    <parent link="LF"/>
    <child link="LFRB"/>
    <axis xyz="0 0 1"/>
    <dynamics damping="0.2" friction="0.0"/>
    <limit effort="2.8" velocity="30"/>
  </joint>
  <link name="LM">
    <inertial>
      <origin rpy="0 0 0" xyz="4.8179E-09 1.5313E-06 0.045042"/>
      <mass value="0.075119"/>
      <inertia ixx="0.00010565" ixy="-1.0649E-07" ixz="-2.3479E-12" iyy="2.7546E-05" iyz="-8.9308E-10" izz="9.6655E-05"/>
    </inertial>
    <visual>
      <origin rpy="0 0 0" xyz="0 0 0"/>
      <geometry>
        <mesh filename="package://wheelleg_description/meshes/Left.STL"/>
      </geometry>
      <material name="">
        <color rgba="1 1 1 1"/>
      </material>
    </visual>
    <collision>
      <origin rpy="0 0 0" xyz="0 0 0"/>
      <geometry>
        <mesh filename="package://wheelleg_description/meshes/Left.STL"/>
      </geometry>
    </collision>
  </link>
  <joint name="LM_Joint" type="continuous">
    <origin rpy="1.5708 -1.5708 3.1416" xyz="0 0.3 0.02"/>
    <parent link="base_link"/>
    <child link="LM"/>
    <axis xyz="0 0 1"/>
    <limit effort="2.8" velocity="30"/>
  </joint>
  <link name="LMRA">
    <inertial>
      <origin rpy="0 0 0" xyz="0.060620953877514 -0.0509052185223456 -0.0160797180106055"/>
      <mass value="0.102065831041357"/>
      <inertia ixx="0.000107618762660542" ixy="6.4058045299092E-05" ixz="1.40721471251035E-07" iyy="0.000426511611787524" iyz="-2.25569567809916E-07" izz="0.000513500369211842"/>
    </inertial>
    <visual>
      <origin rpy="0 0 0" xyz="0 0 0"/>
      <geometry>
        <mesh filename="package://wheelleg_description/meshes/LeftRimA.STL"/>
      </geometry>
      <material name="">
        <color rgba="1 1 1 1"/>
      </material>
    </visual>
    <collision>
      <origin rpy="0 0 0" xyz="0 0 0"/>
      <geometry>
        <mesh filename="package://wheelleg_description/meshes/LeftRimA.STL"/>
      </geometry>
    </collision>
  </link>
  <joint name="LMRA_Joint" type="continuous">
    <origin rpy="3.1416 0 1.5708" xyz="0 -0.08 0.038242"/>
    <parent link="LM"/>
    <child link="LMRA"/>
    <axis xyz="0 0 1"/>
    <dynamics damping="0.2" friction="0.0"/>
    <limit effort="2.8" velocity="30"/>
  </joint>
  <link name="LMRB">
    <inertial>
      <origin rpy="0 0 0" xyz="0.060620953877514 -0.0509052185223458 -0.0160797180106054"/>
      <mass value="0.102065831041357"/>
      <inertia ixx="0.000107618762660542" ixy="6.4058045299092E-05" ixz="1.40721471251074E-07" iyy="0.000426511611787524" iyz="-2.2556956780994E-07" izz="0.000513500369211842"/>
    </inertial>
    <visual>
      <origin rpy="0 0 0" xyz="0 0 0"/>
      <geometry>
        <mesh filename="package://wheelleg_description/meshes/LeftRimB.STL"/>
      </geometry>
      <material name="">
        <color rgba="1 1 1 1"/>
      </material>
    </visual>
    <collision>
      <origin rpy="0 0 0" xyz="0 0 0"/>
      <geometry>
        <mesh filename="package://wheelleg_description/meshes/LeftRimB.STL"/>
      </geometry>
    </collision>
  </link>
  <joint name="LMRB_Joint" type="continuous">
    <origin rpy="3.1416 0 -1.5708" xyz="0 0.08 0.038242"/>
    <parent link="LM"/>
    <child link="LMRB"/>
    <axis xyz="0 0 1"/>
    <dynamics damping="0.2" friction="0.0"/>
    <limit effort="2.8" velocity="30"/>
  </joint>
  <link name="LB">
    <inertial>
      <origin rpy="0 0 0" xyz="4.8179E-09 1.5313E-06 0.045042"/>
      <mass value="0.075119"/>
      <inertia ixx="0.00010565" ixy="-1.0649E-07" ixz="-2.3479E-12" iyy="2.7546E-05" iyz="-8.9308E-10" izz="9.6655E-05"/>
    </inertial>
    <visual>
      <origin rpy="0 0 0" xyz="0 0 0"/>
      <geometry>
        <mesh filename="package://wheelleg_description/meshes/Left.STL"/>
      </geometry>
      <material name="">
        <color rgba="1 1 1 1"/>
      </material>
    </visual>
    <collision>
      <origin rpy="0 0 0" xyz="0 0 0"/>
      <geometry>
        <mesh filename="package://wheelleg_description/meshes/Left.STL"/>
      </geometry>
    </collision>
  </link>
  <joint name="LB_Joint" type="continuous">
    <origin rpy="1.5708 -1.5708 3.1416" xyz="-0.4 0.2 0.02"/>
    <parent link="base_link"/>
    <child link="LB"/>
    <axis xyz="0 0 1"/>
    <limit effort="2.8" velocity="30"/>
  </joint>
  <link name="LBRA">
    <inertial>
      <origin rpy="0 0 0" xyz="0.060620953877514 -0.0509052185223456 -0.0160797180106055"/>
      <mass value="0.102065831041357"/>
      <inertia ixx="0.000107618762660542" ixy="6.4058045299092E-05" ixz="1.40721471251035E-07" iyy="0.000426511611787524" iyz="-2.25569567809916E-07" izz="0.000513500369211842"/>
    </inertial>
    <visual>
      <origin rpy="0 0 0" xyz="0 0 0"/>
      <geometry>
        <mesh filename="package://wheelleg_description/meshes/LeftRimA.STL"/>
      </geometry>
      <material name="">
        <color rgba="1 1 1 1"/>
      </material>
    </visual>
    <collision>
      <origin rpy="0 0 0" xyz="0 0 0"/>
      <geometry>
        <mesh filename="package://wheelleg_description/meshes/LeftRimA.STL"/>
      </geometry>
    </collision>
  </link>
  <joint name="LBRA_Joint" type="continuous">
    <origin rpy="3.1416 0 1.5708" xyz="0 -0.08 0.038242"/>
    <parent link="LB"/>
    <child link="LBRA"/>
    <axis xyz="0 0 1"/>
    <dynamics damping="0.2" friction="0.0"/>
    <limit effort="2.8" velocity="30"/>
  </joint>
  <link name="LBRB">
    <inertial>
      <origin rpy="0 0 0" xyz="0.060620953877514 -0.0509052185223458 -0.0160797180106054"/>
      <mass value="0.102065831041357"/>
      <inertia ixx="0.000107618762660542" ixy="6.4058045299092E-05" ixz="1.40721471251074E-07" iyy="0.000426511611787524" iyz="-2.2556956780994E-07" izz="0.000513500369211842"/>
    </inertial>
    <visual>
      <origin rpy="0 0 0" xyz="0 0 0"/>
      <geometry>
        <mesh filename="package://wheelleg_description/meshes/LeftRimB.STL"/>
      </geometry>
      <material name="">
        <color rgba="1 1 1 1"/>
      </material>
    </visual>
    <collision>
      <origin rpy="0 0 0" xyz="0 0 0"/>
      <geometry>
        <mesh filename="package://wheelleg_description/meshes/LeftRimB.STL"/>
      </geometry>
    </collision>
  </link>
  <joint name="LBRB_Joint" type="continuous">
    <origin rpy="3.1416 0 -1.5708" xyz="0 0.08 0.038242"/>
    <parent link="LB"/>
    <child link="LBRB"/>
    <axis xyz="0 0 1"/>
    <dynamics damping="0.2" friction="0.0"/>
    <limit effort="2.8" velocity="30"/>
  </joint>
  <link name="RF">
    <inertial>
      <origin rpy="0 0 0" xyz="4.8179E-09 1.5313E-06 0.045042"/>
      <mass value="0.075119"/>
      <inertia ixx="0.00010565" ixy="-1.0649E-07" ixz="-2.3479E-12" iyy="2.7546E-05" iyz="-8.9308E-10" izz="9.6655E-05"/>
    </inertial>
    <visual>
      <origin rpy="0 0 0" xyz="0 0 0"/>
      <geometry>
        <mesh filename="package://wheelleg_description/meshes/Right.STL"/>
      </geometry>
      <material name="">
        <color rgba="1 1 1 1"/>
      </material>
    </visual>
    <collision>
      <origin rpy="0 0 0" xyz="0 0 0"/>
      <geometry>
        <mesh filename="package://wheelleg_description/meshes/Right.STL"/>
      </geometry>
    </collision>
  </link>
  <joint name="RF_Joint" type="continuous">
    <origin rpy="1.5708 1.5708 0.0" xyz="0.4 -0.2 0.02"/>
    <parent link="base_link"/>
    <child link="RF"/>
    <axis xyz="0 0 1"/>
    <limit effort="2.8" velocity="30"/>
  </joint>
  <link name="RFRA">
    <inertial>
      <origin rpy="0 0 0" xyz="0.0606209538775138 -0.0509052185223455 0.0159343419031902"/>
      <mass value="0.102065831041357"/>
      <inertia ixx="0.000107618762660542" ixy="6.40580452990925E-05" ixz="1.40721471251091E-07" iyy="0.000426511611787524" iyz="-2.25569567809853E-07" izz="0.000513500369211842"/>
    </inertial>
    <visual>
      <origin rpy="0 0 0" xyz="0 0 0"/>
      <geometry>
        <mesh filename="package://wheelleg_description/meshes/RightRimA.STL"/>
      </geometry>
      <material name="">
        <color rgba="1 1 1 1"/>
      </material>
    </visual>
    <collision>
      <origin rpy="0 0 0" xyz="0 0 0"/>
      <geometry>
        <mesh filename="package://wheelleg_description/meshes/RightRimA.STL"/>
      </geometry>
    </collision>
  </link>
  <joint name="RFRA_Joint" type="continuous">
    <origin rpy="0 0 1.5708" xyz="0 -0.08 0.038244"/>
    <parent link="RF"/>
    <child link="RFRA"/>
    <axis xyz="0 0 1"/>
    <dynamics damping="0.2" friction="0.0"/>
    <limit effort="2.8" velocity="30"/>
  </joint>
  <link name="RFRB">
    <inertial>
      <origin rpy="0 0 0" xyz="0.060620953877514 -0.050905218522346 0.0159343419031902"/>
      <mass value="0.102065831041357"/>
      <inertia ixx="0.000107618762660542" ixy="6.40580452990932E-05" ixz="1.40721471251035E-07" iyy="0.000426511611787523" iyz="-2.25569567810021E-07" izz="0.00051350036921184"/>
    </inertial>
    <visual>
      <origin rpy="0 0 0" xyz="0 0 0"/>
      <geometry>
        <mesh filename="package://wheelleg_description/meshes/RightRimB.STL"/>
      </geometry>
      <material name="">
        <color rgba="1 1 1 1"/>
      </material>
    </visual>
    <collision>
      <origin rpy="0 0 0" xyz="0 0 0"/>
      <geometry>
        <mesh filename="package://wheelleg_description/meshes/RightRimB.STL"/>
      </geometry>
    </collision>
  </link>
  <joint name="RFRB_Joint" type="continuous">
    <origin rpy="0 0 -1.5708" xyz="0 0.08 0.038244"/>
    <parent link="RF"/>
    <child link="RFRB"/>
    <axis xyz="0 0 1"/>
    <dynamics damping="0.2" friction="0.0"/>
    <limit effort="2.8" velocity="30"/>
  </joint>
  <link name="RM">
    <inertial>
      <origin rpy="0 0 0" xyz="4.8179E-09 1.5313E-06 0.045042"/>
      <mass value="0.075119"/>
      <inertia ixx="0.00010565" ixy="-1.0649E-07" ixz="-2.3479E-12" iyy="2.7546E-05" iyz="-8.9308E-10" izz="9.6655E-05"/>
    </inertial>
    <visual>
      <origin rpy="0 0 0" xyz="0 0 0"/>
      <geometry>
        <mesh filename="package://wheelleg_description/meshes/Right.STL"/>
      </geometry>
      <material name="">
        <color rgba="1 1 1 1"/>
      </material>
    </visual>
    <collision>
      <origin rpy="0 0 0" xyz="0 0 0"/>
      <geometry>
        <mesh filename="package://wheelleg_description/meshes/Right.STL"/>
      </geometry>
    </collision>
  </link>
  <joint name="RM_Joint" type="continuous">
    <origin rpy="1.5708 1.5708 0.0" xyz="0 -0.3 0.02"/>
    <parent link="base_link"/>
    <child link="RM"/>
    <axis xyz="0 0 1"/>
    <limit effort="2.8" velocity="30"/>
  </joint>
  <link name="RMRA">
    <inertial>
      <origin rpy="0 0 0" xyz="0.0606209538775138 -0.0509052185223455 0.0159343419031902"/>
      <mass value="0.102065831041357"/>
      <inertia ixx="0.000107618762660542" ixy="6.40580452990925E-05" ixz="1.40721471251091E-07" iyy="0.000426511611787524" iyz="-2.25569567809853E-07" izz="0.000513500369211842"/>
    </inertial>
    <visual>
      <origin rpy="0 0 0" xyz="0 0 0"/>
      <geometry>
        <mesh filename="package://wheelleg_description/meshes/RightRimA.STL"/>
      </geometry>
      <material name="">
        <color rgba="1 1 1 1"/>
      </material>
    </visual>
    <collision>
      <origin rpy="0 0 0" xyz="0 0 0"/>
      <geometry>
        <mesh filename="package://wheelleg_description/meshes/RightRimA.STL"/>
      </geometry>
    </collision>
  </link>
  <joint name="RMRA_Joint" type="continuous">
    <origin rpy="0 0 1.5708" xyz="0 -0.08 0.038244"/>
    <parent link="RM"/>
    <child link="RMRA"/>
    <axis xyz="0 0 1"/>
    <dynamics damping="0.2" friction="0.0"/>
    <limit effort="2.8" velocity="30"/>
  </joint>
  <link name="RMRB">
    <inertial>
      <origin rpy="0 0 0" xyz="0.060620953877514 -0.050905218522346 0.0159343419031902"/>
      <mass value="0.102065831041357"/>
      <inertia ixx="0.000107618762660542" ixy="6.40580452990932E-05" ixz="1.40721471251035E-07" iyy="0.000426511611787523" iyz="-2.25569567810021E-07" izz="0.00051350036921184"/>
    </inertial>
    <visual>
      <origin rpy="0 0 0" xyz="0 0 0"/>
      <geometry>
        <mesh filename="package://wheelleg_description/meshes/RightRimB.STL"/>
      </geometry>
      <material name="">
        <color rgba="1 1 1 1"/>
      </material>
    </visual>
    <collision>
      <origin rpy="0 0 0" xyz="0 0 0"/>
      <geometry>
        <mesh filename="package://wheelleg_description/meshes/RightRimB.STL"/>
      </geometry>
    </collision>
  </link>
  <joint name="RMRB_Joint" type="continuous">
    <origin rpy="0 0 -1.5708" xyz="0 0.08 0.038244"/>
    <parent link="RM"/>
    <child link="RMRB"/>
    <axis xyz="0 0 1"/>
    <dynamics damping="0.2" friction="0.0"/>
    <limit effort="2.8" velocity="30"/>
  </joint>
  <link name="RB">
    <inertial>
      <origin rpy="0 0 0" xyz="4.8179E-09 1.5313E-06 0.045042"/>
      <mass value="0.075119"/>
      <inertia ixx="0.00010565" ixy="-1.0649E-07" ixz="-2.3479E-12" iyy="2.7546E-05" iyz="-8.9308E-10" izz="9.6655E-05"/>
    </inertial>
    <visual>
      <origin rpy="0 0 0" xyz="0 0 0"/>
      <geometry>
        <mesh filename="package://wheelleg_description/meshes/Right.STL"/>
      </geometry>
      <material name="">
        <color rgba="1 1 1 1"/>
      </material>
    </visual>
    <collision>
      <origin rpy="0 0 0" xyz="0 0 0"/>
      <geometry>
        <mesh filename="package://wheelleg_description/meshes/Right.STL"/>
      </geometry>
    </collision>
  </link>
  <joint name="RB_Joint" type="continuous">
    <origin rpy="1.5708 1.5708 0.0" xyz="-0.4 -0.2 0.02"/>
    <parent link="base_link"/>
    <child link="RB"/>
    <axis xyz="0 0 1"/>
    <limit effort="2.8" velocity="30"/>
  </joint>
  <link name="RBRA">
    <inertial>
      <origin rpy="0 0 0" xyz="0.0606209538775138 -0.0509052185223455 0.0159343419031902"/>
      <mass value="0.102065831041357"/>
      <inertia ixx="0.000107618762660542" ixy="6.40580452990925E-05" ixz="1.40721471251091E-07" iyy="0.000426511611787524" iyz="-2.25569567809853E-07" izz="0.000513500369211842"/>
    </inertial>
    <visual>
      <origin rpy="0 0 0" xyz="0 0 0"/>
      <geometry>
        <mesh filename="package://wheelleg_description/meshes/RightRimA.STL"/>
      </geometry>
      <material name="">
        <color rgba="1 1 1 1"/>
      </material>
    </visual>
    <collision>
      <origin rpy="0 0 0" xyz="0 0 0"/>
      <geometry>
        <mesh filename="package://wheelleg_description/meshes/RightRimA.STL"/>
      </geometry>
    </collision>
  </link>
  <joint name="RBRA_Joint" type="continuous">
    <origin rpy="0 0 1.5708" xyz="0 -0.08 0.038244"/>
    <parent link="RB"/>
    <child link="RBRA"/>
    <axis xyz="0 0 1"/>
    <dynamics damping="0.2" friction="0.0"/>
    <limit effort="2.8" velocity="30"/>
  </joint>
  <link name="RBRB">
    <inertial>
      <origin rpy="0 0 0" xyz="0.060620953877514 -0.050905218522346 0.0159343419031902"/>
      <mass value="0.102065831041357"/>
      <inertia ixx="0.000107618762660542" ixy="6.40580452990932E-05" ixz="1.40721471251035E-07" iyy="0.000426511611787523" iyz="-2.25569567810021E-07" izz="0.00051350036921184"/>
    </inertial>
    <visual>
      <origin rpy="0 0 0" xyz="0 0 0"/>
      <geometry>
        <mesh filename="package://wheelleg_description/meshes/RightRimB.STL"/>
      </geometry>
      <material name="">
        <color rgba="1 1 1 1"/>
      </material>
    </visual>
    <collision>
      <origin rpy="0 0 0" xyz="0 0 0"/>
      <geometry>
        <mesh filename="package://wheelleg_description/meshes/RightRimB.STL"/>
      </geometry>
    </collision>
  </link>
  <joint name="RBRB_Joint" type="continuous">
    <origin rpy="0 0 -1.5708" xyz="0 0.08 0.038244"/>
    <parent link="RB"/>
    <child link="RBRB"/>
    <axis xyz="0 0 1"/>
    <dynamics damping="0.2" friction="0.0"/>
    <limit effort="2.8" velocity="30"/>
  </joint>
  <!--load control interface for robot-->
  <gazebo>
    <plugin filename="libgazebo_ros_control.so" name="gazebo_ros_control">
      <robotNamespace>/WheelLeg</robotNamespace>
    </plugin>
  </gazebo>
  <transmission name="tran_LF">
    <type>transmission_interface/SimpleTransmission</type>
    <joint name="LF_Joint">
      <hardwareInterface>hardware_interface/EffortJointInterface</hardwareInterface>
    </joint>
    <actuator name="motor_LF">
      <hardwareInterface>hardware_interface/EffortJointInterface</hardwareInterface>
      <mechanicalReduction>1</mechanicalReduction>
    </actuator>
  </transmission>
  <gazebo reference="LF">
    <material>Gazebo/White</material>
  </gazebo>
  <transmission name="tran_LFRA">
    <type>transmission_interface/SimpleTransmission</type>
    <joint name="LFRA_Joint">
      <hardwareInterface>hardware_interface/EffortJointInterface</hardwareInterface>
    </joint>
    <actuator name="motor_LFRA">
      <hardwareInterface>hardware_interface/EffortJointInterface</hardwareInterface>
      <mechanicalReduction>1</mechanicalReduction>
    </actuator>
  </transmission>
  <gazebo reference="LFRA">
    <material>Gazebo/Black</material>
  </gazebo>
  <transmission name="tran_LFRB">
    <type>transmission_interface/SimpleTransmission</type>
    <joint name="LFRB_Joint">
      <hardwareInterface>hardware_interface/EffortJointInterface</hardwareInterface>
    </joint>
    <actuator name="motor_LFRB">
      <hardwareInterface>hardware_interface/EffortJointInterface</hardwareInterface>
      <mechanicalReduction>1</mechanicalReduction>
    </actuator>
  </transmission>
  <gazebo reference="LFRB">
    <material>Gazebo/Black</material>
  </gazebo>
  <transmission name="tran_LM">
    <type>transmission_interface/SimpleTransmission</type>
    <joint name="LM_Joint">
      <hardwareInterface>hardware_interface/EffortJointInterface</hardwareInterface>
    </joint>
    <actuator name="motor_LM">
      <hardwareInterface>hardware_interface/EffortJointInterface</hardwareInterface>
      <mechanicalReduction>1</mechanicalReduction>
    </actuator>
  </transmission>
  <gazebo reference="LM">
    <material>Gazebo/White</material>
  </gazebo>
  <transmission name="tran_LMRA">
    <type>transmission_interface/SimpleTransmission</type>
    <joint name="LMRA_Joint">
      <hardwareInterface>hardware_interface/EffortJointInterface</hardwareInterface>
    </joint>
    <actuator name="motor_LMRA">
      <hardwareInterface>hardware_interface/EffortJointInterface</hardwareInterface>
      <mechanicalReduction>1</mechanicalReduction>
    </actuator>
  </transmission>
  <gazebo reference="LMRA">
    <material>Gazebo/Black</material>
  </gazebo>
  <transmission name="tran_LMRB">
    <type>transmission_interface/SimpleTransmission</type>
    <joint name="LMRB_Joint">
      <hardwareInterface>hardware_interface/EffortJointInterface</hardwareInterface>
    </joint>
    <actuator name="motor_LMRB">
      <hardwareInterface>hardware_interface/EffortJointInterface</hardwareInterface>
      <mechanicalReduction>1</mechanicalReduction>
    </actuator>
  </transmission>
  <gazebo reference="LMRB">
    <material>Gazebo/Black</material>
  </gazebo>
  <transmission name="tran_LB">
    <type>transmission_interface/SimpleTransmission</type>
    <joint name="LB_Joint">
      <hardwareInterface>hardware_interface/EffortJointInterface</hardwareInterface>
    </joint>
    <actuator name="motor_LB">
      <hardwareInterface>hardware_interface/EffortJointInterface</hardwareInterface>
      <mechanicalReduction>1</mechanicalReduction>
    </actuator>
  </transmission>
  <gazebo reference="LB">
    <material>Gazebo/White</material>
  </gazebo>
  <transmission name="tran_LBRA">
    <type>transmission_interface/SimpleTransmission</type>
    <joint name="LBRA_Joint">
      <hardwareInterface>hardware_interface/EffortJointInterface</hardwareInterface>
    </joint>
    <actuator name="motor_LBRA">
      <hardwareInterface>hardware_interface/EffortJointInterface</hardwareInterface>
      <mechanicalReduction>1</mechanicalReduction>
    </actuator>
  </transmission>
  <gazebo reference="LBRA">
    <material>Gazebo/Black</material>
  </gazebo>
  <transmission name="tran_LBRB">
    <type>transmission_interface/SimpleTransmission</type>
    <joint name="LBRB_Joint">
      <hardwareInterface>hardware_interface/EffortJointInterface</hardwareInterface>
    </joint>
    <actuator name="motor_LBRB">
      <hardwareInterface>hardware_interface/EffortJointInterface</hardwareInterface>
      <mechanicalReduction>1</mechanicalReduction>
    </actuator>
  </transmission>
  <gazebo reference="LBRB">
    <material>Gazebo/Black</material>
  </gazebo>
  <transmission name="tran_RF">
    <type>transmission_interface/SimpleTransmission</type>
    <joint name="RF_Joint">
      <hardwareInterface>hardware_interface/EffortJointInterface</hardwareInterface>
    </joint>
    <actuator name="motor_RF">
      <hardwareInterface>hardware_interface/EffortJointInterface</hardwareInterface>
      <mechanicalReduction>1</mechanicalReduction>
    </actuator>
  </transmission>
  <gazebo reference="RF">
    <material>Gazebo/White</material>
  </gazebo>
  <transmission name="tran_RFRA">
    <type>transmission_interface/SimpleTransmission</type>
    <joint name="RFRA_Joint">
      <hardwareInterface>hardware_interface/EffortJointInterface</hardwareInterface>
    </joint>
    <actuator name="motor_RFRA">
      <hardwareInterface>hardware_interface/EffortJointInterface</hardwareInterface>
      <mechanicalReduction>1</mechanicalReduction>
    </actuator>
  </transmission>
  <gazebo reference="RFRA">
    <material>Gazebo/Black</material>
  </gazebo>
  <transmission name="tran_RFRB">
    <type>transmission_interface/SimpleTransmission</type>
    <joint name="RFRB_Joint">
      <hardwareInterface>hardware_interface/EffortJointInterface</hardwareInterface>
    </joint>
    <actuator name="motor_RFRB">
      <hardwareInterface>hardware_interface/EffortJointInterface</hardwareInterface>
      <mechanicalReduction>1</mechanicalReduction>
    </actuator>
  </transmission>
  <gazebo reference="RFRB">
    <material>Gazebo/Black</material>
  </gazebo>
  <transmission name="tran_RM">
    <type>transmission_interface/SimpleTransmission</type>
    <joint name="RM_Joint">
      <hardwareInterface>hardware_interface/EffortJointInterface</hardwareInterface>
    </joint>
    <actuator name="motor_RM">
      <hardwareInterface>hardware_interface/EffortJointInterface</hardwareInterface>
      <mechanicalReduction>1</mechanicalReduction>
    </actuator>
  </transmission>
  <gazebo reference="RM">
    <material>Gazebo/White</material>
  </gazebo>
  <transmission name="tran_RMRA">
    <type>transmission_interface/SimpleTransmission</type>
    <joint name="RMRA_Joint">
      <hardwareInterface>hardware_interface/EffortJointInterface</hardwareInterface>
    </joint>
    <actuator name="motor_RMRA">
      <hardwareInterface>hardware_interface/EffortJointInterface</hardwareInterface>
      <mechanicalReduction>1</mechanicalReduction>
    </actuator>
  </transmission>
  <gazebo reference="RMRA">
    <material>Gazebo/Black</material>
  </gazebo>
  <transmission name="tran_RMRB">
    <type>transmission_interface/SimpleTransmission</type>
    <joint name="RMRB_Joint">
      <hardwareInterface>hardware_interface/EffortJointInterface</hardwareInterface>
    </joint>
    <actuator name="motor_RMRB">
      <hardwareInterface>hardware_interface/EffortJointInterface</hardwareInterface>
      <mechanicalReduction>1</mechanicalReduction>
    </actuator>
  </transmission>
  <gazebo reference="RMRB">
    <material>Gazebo/Black</material>
  </gazebo>
  <transmission name="tran_RB">
    <type>transmission_interface/SimpleTransmission</type>
    <joint name="RB_Joint">
      <hardwareInterface>hardware_interface/EffortJointInterface</hardwareInterface>
    </joint>
    <actuator name="motor_RB">
      <hardwareInterface>hardware_interface/EffortJointInterface</hardwareInterface>
      <mechanicalReduction>1</mechanicalReduction>
    </actuator>
  </transmission>
  <gazebo reference="RB">
    <material>Gazebo/White</material>
  </gazebo>
  <transmission name="tran_RBRA">
    <type>transmission_interface/SimpleTransmission</type>
    <joint name="RBRA_Joint">
      <hardwareInterface>hardware_interface/EffortJointInterface</hardwareInterface>
    </joint>
    <actuator name="motor_RBRA">
      <hardwareInterface>hardware_interface/EffortJointInterface</hardwareInterface>
      <mechanicalReduction>1</mechanicalReduction>
    </actuator>
  </transmission>
  <gazebo reference="RBRA">
    <material>Gazebo/Black</material>
  </gazebo>
  <transmission name="tran_RBRB">
    <type>transmission_interface/SimpleTransmission</type>
    <joint name="RBRB_Joint">
      <hardwareInterface>hardware_interface/EffortJointInterface</hardwareInterface>
    </joint>
    <actuator name="motor_RBRB">
      <hardwareInterface>hardware_interface/EffortJointInterface</hardwareInterface>
      <mechanicalReduction>1</mechanicalReduction>
    </actuator>
  </transmission>
  <gazebo reference="RBRB">
    <material>Gazebo/Black</material>
  </gazebo>
</robot>

